Workbook

Sheet Results - Global Totals
C1: Impact / kg Food Balance Sheet functional unit (ex. waste)
B2: Food and Waste ('000 t, 2009-11 avg.) | C2: Land Use (m2) | G2: GHG (kg CO2eq, IPCC 2013) | O2: Acid.(kg SO2eq) | P2: Eutr. (kg PO43-eq) | Q2: Freshwater (L) | R2: Str-Wt WU (L eq)
A3: Product | C3: Arable | D3: Fallow | E3: Perm Past | F3: Total | G3: LUC | H3: Feed | I3: Farm | J3: Processing | K3: Transport | L3: Packging | M3: Retail | N3: Total | O3: Total | P3: Total | Q3: Total | R3: Total
A4: Wheat & Rye (Bread) | B4: 482152 | C4: 2.55 | D4: 0.932 | E4: 0 | F4: =SUM(C4:E4) -> 3.482 | G4: 0.1 | H4: 0 | I4: 0.847 | J4: 0.217 | K4: 0.129 | L4: 0.09 | M4: 0.058 | N4: =SUM(G4:M4) -> 1.441 | O4: 0.01209 | P4: 0.00706 | Q4: 567 | R4: 28918
A5: Maize (Meal) | B5: 194554 | C5: 1.171 | D5: 0.457 | E5: 0 | F5: =SUM(C5:E5) -> 1.628 | G5: 0.315 | H5: 0 | I5: 0.475 | J5: 0.052 | K5: 0.06 | L5: 0.06 | M5: 0.026 | N5: =SUM(G5:M5) -> 0.988 | O5: 0.00673 | P5: 0.00226 | Q5: 120 | R5: 6007
A6: Barley (Beer) | B6: 206523 | C6: 0.674 | D6: 0.266 | E6: 0 | F6: =SUM(C6:E6) -> 0.94 | G6: 0.009 | H6: 0 | I6: 0.176 | J6: 0.128 | K6: 0.035 | L6: 0.497 | M6: 0.264 | N6: =SUM(G6:M6) -> 1.109 | O6: 0.00612 | P6: 0.00211 | Q6: 15 | R6: 604
A7: Oatmeal | B7: 4463 | C7: 3.414 | D7: 1.352 | E7: 0 | F7: =SUM(C7:E7) -> 4.766 | G7: 0.001 | H7: 0 | I7: 1.37 | J7: 0.042 | K7: 0.067 | L7: 0.066 | M7: 0.029 | N7: =SUM(G7:M7) -> 1.575 | O7: 0.00697 | P7: 0.00705 | Q7: 302 | R7: 11774
A8: Rice | B8: 397780 | C8: 2.093 | D8: 0.308 | E8: 0 | F8: =SUM(C8:E8) -> 2.401 | G8: -0.022 | H8: 0 | I8: 3.553 | J8: 0.065 | K8: 0.096 | L8: 0.084 | M8: 0.063 | N8: =SUM(G8:M8) -> 3.839 | O8: 0.02357 | P8: 0.02972 | Q8: 1962 | R8: 43275
A9: Potatoes | B9: 332343 | C9: 0.498 | D9: 0.145 | E9: 0 | F9: =SUM(C9:E9) -> 0.643 | G9: -0.001 | H9: 0 | I9: 0.193 | J9: 0 | K9: 0.094 | L9: 0.045 | M9: 0.039 | N9: =SUM(G9:M9) -> 0.37 | O9: 0.00323 | P9: 0.00255 | Q9: 43 | R9: 2027
A10: Cassava | B10: 173814 | C10: 0.934 | D10: 0.32 | E10: 0 | F10: =SUM(C10:E10) -> 1.254 | G10: 0.589 | H10: 0 | I10: 0.22 | J10: 0 | K10: 0.094 | L10: 0.045 | M10: 0.039 | N10: =SUM(G10:M10) -> 0.987 | O10: 0.00298 | P10: 0.00056 | Q10: 0 | R10: 0
A11: Cane Sugar | B11: 141702 | C11: 1.213 | D11: 0.381 | E11: 0 | F11: =SUM(C11:E11) -> 1.594 | G11: 1.247 | H11: 0 | I11: 0.485 | J11: 0.037 | K11: 0.784 | L11: 0.083 | M11: 0.036 | N11: =SUM(G11:M11) -> 2.672 | O11: 0.01537 | P11: 0.0136 | Q11: 492 | R11: 13096
A12: Beet Sugar | B12: 34038 | C12: 1.159 | D12: 0.274 | E12: 0 | F12: =SUM(C12:E12) -> 1.433 | G12: 0 | H12: 0 | I12: 0.536 | J12: 0.242 | K12: 0.629 | L12: 0.09 | M12: 0.039 | N12: =SUM(G12:M12) -> 1.536 | O12: 0.01076 | P12: 0.00437 | Q12: 170 | R12: 7413
A13: Other Pulses | B13: 42765 | C13: 9.851 | D13: 3.769 | E13: 0 | F13: =SUM(C13:E13) -> 13.62 | G13: 0.033 | H13: 0 | I13: 1.089 | J13: 0 | K13: 0.096 | L13: 0.353 | M13: 0.039 | N13: =SUM(G13:M13) -> 1.61 | O13: 0.01913 | P13: 0.01501 | Q13: 364 | R13: 18670
A14: Peas | B14: 6026 | C14: 5.354 | D14: 1.384 | E14: 0 | F14: =SUM(C14:E14) -> 6.738 | G14: 0 | H14: 0 | I14: 0.717 | J14: 0 | K14: 0.095 | L14: 0.045 | M14: 0.039 | N14: =SUM(G14:M14) -> 0.896 | O14: 0.00759 | P14: 0.00683 | Q14: 353 | R14: 24856
A15: Nuts | B15: 15296 | C15: 4.681 | D15: 0.399 | E15: 0 | F15: =SUM(C15:E15) -> 5.08 | G15: -2.052 | H15: 0 | I15: 2.126 | J15: 0.032 | K15: 0.067 | L15: 0.078 | M15: 0.027 | N15: =SUM(G15:M15) -> 0.278 | O15: 0.01904 | P15: 0.0088 | Q15: 1914 | R15: 106382
... A53: Butter, Cream & Ghee | B53: 12066 | C53: 1.327 | D53: 0.402 | E53: 6.275 | F53: =SUM(C53:E53) -> 8.004 | G53: 0.495 | H53: 0.236 | I53: 1.458 | J53: 0.149 | K53: 0.09 | L53: 0.097 | M53: 0.256 | N53: =SUM(G53:M53) -> 2.781 | O53: 0.01766 | P53: 0.00934 | Q53: 533 | R53: 16951

Sheet totals
A1: Product | B1: Food and Waste ('000 t, 2009-11 avg.) | C1: Land Use (m2) | D1: GHG (kg CO2eq, IPCC 2013) | E1: Eutr. (kg PO43-eq) | F1: Str-Wt WU (L eq)
A2: Wheat & Rye (Bread) | B2: 482152 | C2: 3.482 | D2: 1.441 | E2: 0.00706 | F2: 28918
A3: Maize (Meal) | B3: 194554 | C3: 1.628 | D3: 0.988 | E3: 0.00226 | F3: 6007
A4: Barley (Beer) | B4: 206523 | C4: 0.94 | D4: 1.109 | E4: 0.00211 | F4: 604
A5: Oatmeal | B5: 4463 | C5: 4.766 | D5: 1.575 | E5: 0.00705 | F5: 11774
A6: Rice | B6: 397780 | C6: 2.401 | D6: 3.839 | E6: 0.02972 | F6: 43275
A7: Potatoes | B7: 332343 | C7: 0.643 | D7: 0.37 | E7: 0.00255 | F7: 2027
A8: Cassava | B8: 173814 | C8: 1.254 | D8: 0.987 | E8: 0.00056 | F8: 0
A9: Cane Sugar | B9: 141702 | C9: 1.594 | D9: 2.672 | E9: 0.0136 | F9: 13096
A10: Beet Sugar | B10: 34038 | C10: 1.433 | D10: 1.536 | E10: 0.00437 | F10: 7413
A11: Other Pulses | B11: 42765 | C11: 13.62 | D11: 1.61 | E11: 0.01501 | F11: 18670
A12: Peas | B12: 6026 | C12: 6.738 | D12: 0.896 | E12: 0.00683 | F12: 24856
A13: Nuts | B13: 15296 | C13: 5.08 | D13: 0.278 | E13: 0.0088 | F13: 106382
... A51: Butter, Cream & Ghee | B51: 12066 | C51: 8.004 | D51: 2.781 | E51: 0.00934 | F51: 16951

Sheet regrouped
A1: Product | B1: Food and Waste ('000 t, 2009-11 avg.) | C1: Land Use (m2) | D1: GHG (kg CO2eq, IPCC 2013) | E1: Eutr. (kg PO43-eq) | F1: Str-Wt WU (L eq)
A2: Wheat & Rye (Bread) | B2: 482152 | C2: 3.482 | D2: 1.441 | E2: 0.00706 | F2: 28918
A3: Maize (Meal) | B3: 194554 | C3: 1.628 | D3: 0.988 | E3: 0.00226 | F3: 6007
A4: Barley (Beer) | B4: 206523 | C4: 0.94 | D4: 1.109 | E4: 0.00211 | F4: 604
A5: Oatmeal | B5: 4463 | C5: 4.766 | D5: 1.575 | E5: 0.00705 | F5: 11774
A6: Rice | B6: 397780 | C6: 2.401 | D6: 3.839 | E6: 0.02972 | F6: 43275
A7: Potatoes | B7: 332343 | C7: 0.643 | D7: 0.37 | E7: 0.00255 | F7: 2027
A8: Cassava | B8: 173814 | C8: 1.254 | D8: 0.987 | E8: 0.00056 | F8: 0
A9: Sugar | B9: =SUM(totals!B9:B10) -> 175740 | C9: =(totals!C9*totals!$B9+totals!C10*totals!$B10)/regrouped!$B9 -> 1.5628169 | D9: =(totals!D9*totals!$B9+totals!D10*totals!$B10)/regrouped!$B9 -> 2.4519751 | E9: =(totals!E9*totals!$B9+totals!E10*totals!$B10)/regrouped!$B9 -> 0.011812298 | F9: =(totals!F9*totals!$B9+totals!F10*totals!$B10)/regrouped!$B9 -> 11995.295
A10: Other Pulses | B10: 42765 | C10: 13.62 | D10: 1.61 | E10: 0.01501 | F10: 18670
A11: Peas | B11: 6026 | C11: 6.738 | D11: 0.896 | E11: 0.00683 | F11: 24856
A12: Nuts | B12: 15296 | C12: 5.08 | D12: 0.278 | E12: 0.0088 | F12: 106382
A13: Groundnuts | B13: 11827 | C13: 6.971 | D13: 2.497 | E13: 0.01117 | F13: 48147
A14: Soymilk | B14: 33318 | C14: 0.592 | D14: 0.914 | E14: 0.00097 | F14: 894
A15: Tofu | B15: 11853 | C15: 3.154 | D15: 2.871 | E15: 0.00553 | F15: 4785
A16: Oil | B16: =SUM(totals!B17:B21) + totals!B46 -> 77105 | C16: =(totals!C17*totals!$B17+totals!C18*totals!$B18+totals!C19*totals!$B19+totals!C20*totals!$B20+totals!C21*totals!$B21+totals!C46*totals!$B46)/regrouped!$B16 -> 10.113423 | D16: =(totals!D17*totals!$B17+totals!D18*totals!$B18+totals!D19*totals!$B19+totals!D20*totals!$B20+totals!D21*totals!$B21+totals!D46*totals!$B46)/regrouped!$B16 -> 5.7518207 | E16: =(totals!E17*totals!$B17+totals!E18*totals!$B18+totals!E19*totals!$B19+totals!E20*totals!$B20+totals!E21*totals!$B21+totals!E46*totals!$B46)/regrouped!$B16 -> 0.019732384 | F16: =(totals!F17*totals!$B17+totals!F18*totals!$B18+totals!F19*totals!$B19+totals!F20*totals!$B20+totals!F21*totals!$B21+totals!F46*totals!$B46)/regrouped!$B16 -> 21572.249
A17: Tomatoes | B17: 148957 | C17: 0.51 | D17: 1.427 | E17: 0.00481 | F17: 4013
A18: Onions & Leeks | B18: 77927 | C18: 0.285 | D18: 0.395 | E18: 0.0023 | F18: 746
A19: Root Vegetables | B19: 35154 | C19: 0.263 | D19: 0.365 | E19: 0.00132 | F19: 776
A20: Brassicas | B20: 77045 | C20: 0.452 | D20: 0.437 | E20: 0.00414 | F20: 6878
A21: Other Vegetables | B21: 654375 | C21: 0.31 | D21: 0.455 | E21: 0.00186 | F21: 3958
A22: Citrus Fruit | B22: 127923 | C22: 0.675 | D22: 0.317 | E22: 0.00157 | F22: 3678
A23: Bananas | B23: 128971 | C23: 1.23 | D23: 0.678 | E23: 0.00225 | F23: 491
A24: Apples | B24: 75781 | C24: 0.493 | D24: 0.357 | E24: 0.00115 | F24: 10007
A25: Berries & Grapes | B25: 67079 | C25: 1.64 | D25: 1.214 | E25: 0.00531 | F25: 15180
A26: Wine | B26: 26013 | C26: 1.553 | D26: 1.585 | E26: 0.00402 | F26: 1003
A27: Other Fruit | B27: 210650 | C27: 0.61 | D27: 0.75 | E27: 0.00179 | F27: 7771
A28: Coffee | B28: 7778 | C28: 11.721 | D28: 16.477 | E28: 0.0602 | F28: 182
A29: Dark Chocolate | B29: 4416 | C29: 23.693 | D29: 18.681 | E29: 0.03061 | F29: 1097
A30: Beef | B30: =SUM(totals!B35:B36) -> 71996 | C30: =(totals!C35*totals!$B35+totals!C36*totals!$B36)/regrouped!$B30 -> 120.36399 | D30: =(totals!D35*totals!$B35+totals!D36*totals!$B36)/regrouped!$B30 -> 42.771968 | E30: =(totals!E35*totals!$B35+totals!E36*totals!$B36)/regrouped!$B30 -> 0.19115809 | F30: =(totals!F35*totals!$B35+totals!F36*totals!$B36)/regrouped!$B30 -> 44809.88
A31: Lamb & Mutton | B31: 14195 | C31: 223.306 | D31: 24.415 | E31: 0.05965 | F31: 85193
A32: Pig Meat | B32: 112892 | C32: 10.156 | D32: 7.282 | E32: 0.04416 | F32: 40028
A33: Poultry Meat | B33: 96439 | C33: 7.49 | D33: 6.092 | E33: 0.02957 | F33: 8828
A34: Milk | B34: 470267 | C34: 8.004 | D34: 2.781 | E34: 0.00934 | F34: 16951
A35: Cheese | B35: 21191 | C35: 80.642 | D35: 21.24 | E35: 0.08875 | F35: 155464
A36: Eggs | B36: 63489 | C36: 6.049 | D36: 4.507 | E36: 0.02102 | F36: 17315
A37: Fish (farmed) | B37: 45223 | C37: 3.378 | D37: 5.183 | E37: 0.09207 | F37: 13691
A38: Crustaceans (farmed) | B38: 10633 | C38: 1.429 | D38: 11.854 | E38: 0.09787 | F38: 50685
A39: Cereals & Oilcrops Misc. | B39: 97562 | C39: 2.961 | D39: 1.313 | E39: 0.00569 | F39: 22262
A40: Sweeteners & Honey | B40: 21564 | C40: 0 | D40: 0.97 | E40: 0.00218 | F40: 0
...

Sheet mushrooms
A1: Source | B1: Type | C1: GHG (kg CO2 eq / kg) | D1: Freshwater eutrophication (g of P eq / kg) | E1: Scarcity-weighted water use ( m3 eq / kg) | F1: Land use (sq ft / lb) | G1: Notes 1 | H1: Notes 2
A2: Goglio et al 2024 | B2: Agaricus bisporus mushroom | C2: =(0.521 + 0.931 + 1.55)/3 -> 1.0006667 | D2: =(2.34 + 2.34*0.087 + 2.34*0.297)/3 -> 1.07952 | E2: =(1.71 + 1.71*0.119 + 1.71*0.079)/3 -> 0.68286 | G2: I averaged values for three European countries.
A3: USDA | B3: Agaricus bisporus mushroom | F3: =1/6.55 -> 0.15267176 | G3: Inverted 6.55 pounds per square foot
A7: Converted units: | C7: Land use (m2 / kg) | D7: GHG (kg CO2 eq / kg) | E7: Freshwater eutrophication (kg of P eq / kg) | F7: Scarcity-weighted water use ( L eq / kg)
C8: =1/6.55*0.0929/0.4536 -> 0.031268091 | D8: =(0.521 + 0.931 + 1.55)/3 -> 1.0006667 | E8: =(2.34 + 2.34*0.087 + 2.34*0.297)/3/1000 -> 0.00107952 | F8: =(1.71 + 1.71*0.119 + 1.71*0.079)/3*1000 -> 682.86

Sheet augmented w mushrooms
A1: Product | B1: Food and Waste ('000 t, 2009-11 avg.) | C1: Land Use (m2) | D1: GHG (kg CO2eq, IPCC 2013) | E1: Eutr. (kg PO43-eq) | F1: Str-Wt WU (L eq)
A2: Wheat & Rye (Bread) | B2: 482152 | C2: 3.482 | D2: 1.441 | E2: 0.00706 | F2: 28918
A3: Maize (Meal) | B3: 194554 | C3: 1.628 | D3: 0.988 | E3: 0.00226 | F3: 6007
A4: Barley (Beer) | B4: 206523 | C4: 0.94 | D4: 1.109 | E4: 0.00211 | F4: 604
A5: Oatmeal | B5: 4463 | C5: 4.766 | D5: 1.575 | E5: 0.00705 | F5: 11774
A6: Rice | B6: 397780 | C6: 2.401 | D6: 3.839 | E6: 0.02972 | F6: 43275
A7: Potatoes | B7: 332343 | C7: 0.643 | D7: 0.37 | E7: 0.00255 | F7: 2027
A8: Cassava | B8: 173814 | C8: 1.254 | D8: 0.987 | E8: 0.00056 | F8: 0
A9: Sugar | B9: =SUM(totals!B9:B10) -> 175740 | C9: =(totals!C9*totals!$B9+totals!C10*totals!$B10)/'augmented w mushrooms'!$B9 -> 1.5628169 | D9: =(totals!D9*totals!$B9+totals!D10*totals!$B10)/'augmented w mushrooms'!$B9 -> 2.4519751 | E9: =(totals!E9*totals!$B9+totals!E10*totals!$B10)/'augmented w mushrooms'!$B9 -> 0.011812298 | F9: =(totals!F9*totals!$B9+totals!F10*totals!$B10)/'augmented w mushrooms'!$B9 -> 11995.295
A10: Other Pulses | B10: 42765 | C10: 13.62 | D10: 1.61 | E10: 0.01501 | F10: 18670
A11: Peas | B11: 6026 | C11: 6.738 | D11: 0.896 | E11: 0.00683 | F11: 24856
A12: Nuts | B12: 15296 | C12: 5.08 | D12: 0.278 | E12: 0.0088 | F12: 106382
A13: Groundnuts | B13: 11827 | C13: 6.971 | D13: 2.497 | E13: 0.01117 | F13: 48147
A14: Soymilk | B14: 33318 | C14: 0.592 | D14: 0.914 | E14: 0.00097 | F14: 894
A15: Tofu | B15: 11853 | C15: 3.154 | D15: 2.871 | E15: 0.00553 | F15: 4785
A16: Oil | B16: =SUM(totals!B17:B21) + totals!B46 -> 77105 | C16: =(totals!C17*totals!$B17+totals!C18*totals!$B18+totals!C19*totals!$B19+totals!C20*totals!$B20+totals!C21*totals!$B21+totals!C46*totals!$B46)/'augmented w mushrooms'!$B16 -> 10.113423 | D16: =(totals!D17*totals!$B17+totals!D18*totals!$B18+totals!D19*totals!$B19+totals!D20*totals!$B20+totals!D21*totals!$B21+totals!D46*totals!$B46)/'augmented w mushrooms'!$B16 -> 5.7518207 | E16: =(totals!E17*totals!$B17+totals!E18*totals!$B18+totals!E19*totals!$B19+totals!E20*totals!$B20+totals!E21*totals!$B21+totals!E46*totals!$B46)/'augmented w mushrooms'!$B16 -> 0.019732384 | F16: =(totals!F17*totals!$B17+totals!F18*totals!$B18+totals!F19*totals!$B19+totals!F20*totals!$B20+totals!F21*totals!$B21+totals!F46*totals!$B46)/'augmented w mushrooms'!$B16 -> 21572.249
A17: Tomatoes | B17: 148957 | C17: 0.51 | D17: 1.427 | E17: 0.00481 | F17: 4013
A18: Onions & Leeks | B18: 77927 | C18: 0.285 | D18: 0.395 | E18: 0.0023 | F18: 746
A19: Root Vegetables | B19: 35154 | C19: 0.263 | D19: 0.365 | E19: 0.00132 | F19: 776
A20: Brassicas | B20: 77045 | C20: 0.452 | D20: 0.437 | E20: 0.00414 | F20: 6878
A21: Other Vegetables | B21: 654375 | C21: 0.31 | D21: 0.455 | E21: 0.00186 | F21: 3958
A22: Citrus Fruit | B22: 127923 | C22: 0.675 | D22: 0.317 | E22: 0.00157 | F22: 3678
A23: Bananas | B23: 128971 | C23: 1.23 | D23: 0.678 | E23: 0.00225 | F23: 491
A24: Apples | B24: 75781 | C24: 0.493 | D24: 0.357 | E24: 0.00115 | F24: 10007
A25: Berries & Grapes | B25: 67079 | C25: 1.64 | D25: 1.214 | E25: 0.00531 | F25: 15180
A26: Wine | B26: 26013 | C26: 1.553 | D26: 1.585 | E26: 0.00402 | F26: 1003
A27: Other Fruit | B27: 210650 | C27: 0.61 | D27: 0.75 | E27: 0.00179 | F27: 7771
A28: Coffee | B28: 7778 | C28: 11.721 | D28: 16.477 | E28: 0.0602 | F28: 182
A29: Dark Chocolate | B29: 4416 | C29: 23.693 | D29: 18.681 | E29: 0.03061 | F29: 1097
A30: Beef | B30: =SUM(totals!B35:B36) -> 71996 | C30: =(totals!C35*totals!$B35+totals!C36*totals!$B36)/'augmented w mushrooms'!$B30 -> 120.36399 | D30: =(totals!D35*totals!$B35+totals!D36*totals!$B36)/'augmented w mushrooms'!$B30 -> 42.771968 | E30: =(totals!E35*totals!$B35+totals!E36*totals!$B36)/'augmented w mushrooms'!$B30 -> 0.19115809 | F30: =(totals!F35*totals!$B35+totals!F36*totals!$B36)/'augmented w mushrooms'!$B30 -> 44809.88
A31: Lamb & Mutton | B31: 14195 | C31: 223.306 | D31: 24.415 | E31: 0.05965 | F31: 85193
A32: Pig Meat | B32: 112892 | C32: 10.156 | D32: 7.282 | E32: 0.04416 | F32: 40028
A33: Poultry Meat | B33: 96439 | C33: 7.49 | D33: 6.092 | E33: 0.02957 | F33: 8828
A34: Milk | B34: 470267 | C34: 8.004 | D34: 2.781 | E34: 0.00934 | F34: 16951
A35: Cheese | B35: 21191 | C35: 80.642 | D35: 21.24 | E35: 0.08875 | F35: 155464
A36: Eggs | B36: 63489 | C36: 6.049 | D36: 4.507 | E36: 0.02102 | F36: 17315
A37: Fish (farmed) | B37: 45223 | C37: 3.378 | D37: 5.183 | E37: 0.09207 | F37: 13691
A38: Crustaceans (farmed) | B38: 10633 | C38: 1.429 | D38: 11.854 | E38: 0.09787 | F38: 50685
A39: Cereals & Oilcrops Misc. | B39: 97562 | C39: 2.961 | D39: 1.313 | E39: 0.00569 | F39: 22262
A40: Sweeteners & Honey | B40: 21564 | C40: 0 | D40: 0.97 | E40: 0.00218 | F40: 0
...

Sheet augmented w condiments
A1: Product | B1: Food and Waste ('000 t, 2009-11 avg.) | C1: Land Use (m2) | D1: GHG (kg CO2eq, IPCC 2013) | E1: Eutr. (kg PO43-eq) | F1: Str-Wt WU (L eq)
A2: Wheat & Rye (Bread) | B2: 482152 | C2: 3.482 | D2: 1.441 | E2: 0.00706 | F2: 28918
A3: Maize (Meal) | B3: 194554 | C3: 1.628 | D3: 0.988 | E3: 0.00226 | F3: 6007
A4: Barley (Beer) | B4: 206523 | C4: 0.94 | D4: 1.109 | E4: 0.00211 | F4: 604
A5: Oatmeal | B5: 4463 | C5: 4.766 | D5: 1.575 | E5: 0.00705 | F5: 11774
A6: Rice | B6: 397780 | C6: 2.401 | D6: 3.839 | E6: 0.02972 | F6: 43275
A7: Potatoes | B7: 332343 | C7: 0.643 | D7: 0.37 | E7: 0.00255 | F7: 2027
A8: Cassava | B8: 173814 | C8: 1.254 | D8: 0.987 | E8: 0.00056 | F8: 0
A9: Sugar | B9: =SUM(totals!B9:B10) -> 175740 | C9: =(totals!C9*totals!$B9+totals!C10*totals!$B10)/'augmented w condiments'!$B9 -> 1.5628169 | D9: =(totals!D9*totals!$B9+totals!D10*totals!$B10)/'augmented w condiments'!$B9 -> 2.4519751 | E9: =(totals!E9*totals!$B9+totals!E10*totals!$B10)/'augmented w condiments'!$B9 -> 0.011812298 | F9: =(totals!F9*totals!$B9+totals!F10*totals!$B10)/'augmented w condiments'!$B9 -> 11995.295
A10: Other Pulses | B10: 42765 | C10: 13.62 | D10: 1.61 | E10: 0.01501 | F10: 18670
A11: Peas | B11: 6026 | C11: 6.738 | D11: 0.896 | E11: 0.00683 | F11: 24856
A12: Nuts | B12: 15296 | C12: 5.08 | D12: 0.278 | E12: 0.0088 | F12: 106382
A13: Groundnuts | B13: 11827 | C13: 6.971 | D13: 2.497 | E13: 0.01117 | F13: 48147
A14: Soymilk | B14: 33318 | C14: 0.592 | D14: 0.914 | E14: 0.00097 | F14: 894
A15: Tofu | B15: 11853 | C15: 3.154 | D15: 2.871 | E15: 0.00553 | F15: 4785
A16: Oil | B16: =SUM(totals!B17:B21) + totals!B46 -> 77105 | C16: =(totals!C17*totals!$B17+totals!C18*totals!$B18+totals!C19*totals!$B19+totals!C20*totals!$B20+totals!C21*totals!$B21+totals!C46*totals!$B46)/'augmented w condiments'!$B16 -> 10.113423 | D16: =(totals!D17*totals!$B17+totals!D18*totals!$B18+totals!D19*totals!$B19+totals!D20*totals!$B20+totals!D21*totals!$B21+totals!D46*totals!$B46)/'augmented w condiments'!$B16 -> 5.7518207 | E16: =(totals!E17*totals!$B17+totals!E18*totals!$B18+totals!E19*totals!$B19+totals!E20*totals!$B20+totals!E21*totals!$B21+totals!E46*totals!$B46)/'augmented w condiments'!$B16 -> 0.019732384 | F16: =(totals!F17*totals!$B17+totals!F18*totals!$B18+totals!F19*totals!$B19+totals!F20*totals!$B20+totals!F21*totals!$B21+totals!F46*totals!$B46)/'augmented w condiments'!$B16 -> 21572.249
A17: Tomatoes | B17: 148957 | C17: 0.51 | D17: 1.427 | E17: 0.00481 | F17: 4013
A18: Onions & Leeks | B18: 77927 | C18: 0.285 | D18: 0.395 | E18: 0.0023 | F18: 746
A19: Root Vegetables | B19: 35154 | C19: 0.263 | D19: 0.365 | E19: 0.00132 | F19: 776
A20: Brassicas | B20: 77045 | C20: 0.452 | D20: 0.437 | E20: 0.00414 | F20: 6878
A21: Other Vegetables | B21: 654375 | C21: 0.31 | D21: 0.455 | E21: 0.00186 | F21: 3958
A22: Citrus Fruit | B22: 127923 | C22: 0.675 | D22: 0.317 | E22: 0.00157 | F22: 3678
A23: Bananas | B23: 128971 | C23: 1.23 | D23: 0.678 | E23: 0.00225 | F23: 491
A24: Apples | B24: 75781 | C24: 0.493 | D24: 0.357 | E24: 0.00115 | F24: 10007
A25: Berries & Grapes | B25: 67079 | C25: 1.64 | D25: 1.214 | E25: 0.00531 | F25: 15180
A26: Wine | B26: 26013 | C26: 1.553 | D26: 1.585 | E26: 0.00402 | F26: 1003
A27: Other Fruit | B27: 210650 | C27: 0.61 | D27: 0.75 | E27: 0.00179 | F27: 7771
A28: Coffee | B28: 7778 | C28: 11.721 | D28: 16.477 | E28: 0.0602 | F28: 182
A29: Dark Chocolate | B29: 4416 | C29: 23.693 | D29: 18.681 | E29: 0.03061 | F29: 1097
A30: Beef | B30: =SUM(totals!B35:B36) -> 71996 | C30: =(totals!C35*totals!$B35+totals!C36*totals!$B36)/'augmented w condiments'!$B30 -> 120.36399 | D30: =(totals!D35*totals!$B35+totals!D36*totals!$B36)/'augmented w condiments'!$B30 -> 42.771968 | E30: =(totals!E35*totals!$B35+totals!E36*totals!$B36)/'augmented w condiments'!$B30 -> 0.19115809 | F30: =(totals!F35*totals!$B35+totals!F36*totals!$B36)/'augmented w condiments'!$B30 -> 44809.88
A31: Lamb & Mutton | B31: 14195 | C31: 223.306 | D31: 24.415 | E31: 0.05965 | F31: 85193
A32: Pig Meat | B32: 112892 | C32: 10.156 | D32: 7.282 | E32: 0.04416 | F32: 40028
A33: Poultry Meat | B33: 96439 | C33: 7.49 | D33: 6.092 | E33: 0.02957 | F33: 8828
A34: Milk | B34: 470267 | C34: 8.004 | D34: 2.781 | E34: 0.00934 | F34: 16951
A35: Cheese | B35: 21191 | C35: 80.642 | D35: 21.24 | E35: 0.08875 | F35: 155464
A36: Eggs | B36: 63489 | C36: 6.049 | D36: 4.507 | E36: 0.02102 | F36: 17315
A37: Fish (farmed) | B37: 45223 | C37: 3.378 | D37: 5.183 | E37: 0.09207 | F37: 13691
A38: Crustaceans (farmed) | B38: 10633 | C38: 1.429 | D38: 11.854 | E38: 0.09787 | F38: 50685
A39: Cereals & Oilcrops Misc. | B39: 97562 | C39: 2.961 | D39: 1.313 | E39: 0.00569 | F39: 22262
A40: Sweeteners & Honey | B40: 21564 | C40: 0 | D40: 0.97 | E40: 0.00218 | F40: 0
...

Sheet lca names to ingredient names
A1: Environmental Database Food Categories | B1: Recipe Database Food Categories | C1: Environmental Data Source
A2: Wheat & Rye (Bread) | B2: breadcrumb
A3: Wheat & Rye (Bread) | B3: bulgur
A4: Wheat & Rye (Bread) | B4: bun
A5: Wheat & Rye (Bread) | B5: cracker
A6: Wheat & Rye (Bread) | B6: dough
A7: Wheat & Rye (Bread) | B7: flour
A8: Wheat & Rye (Bread) | B8: noodle
A9: Wheat & Rye (Bread) | B9: pasta
A10: Wheat & Rye (Bread) | B10: tortilla
A11: Wheat & Rye (Bread) | B11: wheat germ
A12: Maize (Meal) | B12: corn
A13: Maize (Meal) | B13: cornflour
... A18: Potatoes | B18: potato
A19: Cassava
A20: Sugar | B20: brown sugar
A21: Sugar | B21: sugar
A22: Other Pulses | B22: bean
A23: Other Pulses | B23: lentil
A24: Peas | B24: chickpea
A25: Nuts | B25: almond
A26: Nuts | B26: walnut
A27: Groundnuts | B27: peanut
A28: Soymilk | B28: soy sauce
A29: Tofu | B29: tofu
A30: Oil | B30: oil
A31: Tomatoes | B31: tomato
... A70: Citrus Fruit | B70: orange
A71: Bananas
A72: Apples | B72: apple
A73: Berries & Grapes | B73: cranberry
A74: Wine | B74: wine
A75: Other Fruit | B75: avocado
A76: Other Fruit | B76: mango
A77: Other Fruit | B77: guacamole
A78: Other Fruit | B78: olive
A79: Other Fruit | B79: pineapple
A80: Coffee
A81: Dark Chocolate
A82: Beef | B82: beef
...
